<?xml version="1.0" ?>
<!-- =================================================================================== -->
<!-- |    This document was autogenerated by xacro from urdf/pico.urdf.xacro           | -->
<!-- |    EDITING THIS FILE BY HAND IS NOT RECOMMENDED                                 | -->
<!-- =================================================================================== -->
<robot name="pico">
  <!-- ========================= Link & Joint ================================ -->
  <!--  Base -->
  <link name="base_footprint"/>
  <joint name="base_joint" type="fixed">
    <origin xyz="0 0 0.024"/>
    <parent link="base_footprint"/>
    <child link="base_link"/>
  </joint>
  <link name="base_link">
    <visual>
      <origin rpy="0 0 0" xyz="0.0168 0.0282 -0.0085"/>
      <geometry>
        <mesh filename="meshes/base_link.stl" scale="0.001 0.001 0.001"/>
      </geometry>
    </visual>
    <visual>
      <origin rpy="0 0 3.14" xyz="0.0015 0 0.0313"/>
      <geometry>
        <mesh filename="meshes/pico3_main.stl" scale="0.001 0.001 0.001"/>
      </geometry>
    </visual>
    <visual>
      <origin rpy="0 0 1.57" xyz="0.04355555 0 0.012"/>
      <geometry>
        <mesh filename="meshes/pico3_sensor.stl" scale="0.001 0.001 0.001"/>
      </geometry>
    </visual>
    <visual>
      <origin rpy="0 0 0" xyz="-0.0495 0 0.02"/>
      <geometry>
        <mesh filename="meshes/pico3_power.stl" scale="0.001 0.001 0.001"/>
      </geometry>
    </visual>
  </link>
  <joint name="right_wheel_joint" type="continuous">
    <origin rpy="-3.14 0 0" xyz="0 -0.037 0"/>
    <axis xyz="0 -1 0"/>
    <parent link="base_link"/>
    <child link="right_wheel"/>
  </joint>
  <link name="right_wheel">
    <visual>
      <origin rpy="0 0 0" xyz="0.016588 -0.009495 -0.010064"/>
      <geometry>
        <mesh filename="meshes/wheel_link.stl" scale="0.001 0.001 0.001"/>
      </geometry>
    </visual>
  </link>
  <joint name="left_wheel_joint" type="continuous">
    <origin rpy="0 0 0" xyz="0 0.037 0"/>
    <axis xyz="0 1 0"/>
    <parent link="base_link"/>
    <child link="left_wheel"/>
  </joint>
  <link name="left_wheel">
    <visual>
      <origin rpy="0 0 0" xyz="0.016588 -0.009495 -0.010064"/>
      <geometry>
        <mesh filename="meshes/wheel_link.stl" scale="0.001 0.001 0.001"/>
      </geometry>
    </visual>
  </link>
</robot>
